<div dir="ltr">I have written a small code in python 2.7 for launching 4 independent processes on the shell viasubprocess, using the library mpi4py. I am getting ORTE_ERROR_LOG and I would like to understand where it is happening and why.<div><br></div><div>This is my code:</div><div><br><pre class="" style="margin-top:0px;padding:5px;border:0px;overflow:auto;width:auto;max-height:600px;word-wrap:normal">#!/usr/bin/python<br>import subprocess<br>import re<br>import sys<br>from mpi4py import MPI<br><br>def main():<br>    root=&#39;base&#39;<br>    comm = MPI.COMM_WORLD<br>    if comm.rank == 0:<br>        job = [root+str(i) for i in range(4)]<br>    else:<br>        job = None<br><br>    job = comm.scatter(job, root=0)<br>    cmd=&quot;../../montepython/montepython/MontePython.py -conf ../config/default.conf -p ../config/XXXX.param -o ../chains/XXXX  -N 10000 &gt; XXXX.log&quot;<br><br>    cmd_job = re.sub(r&quot;XXXX&quot;, job, cmd)<br>    subprocess.check_call(cmd_job, shell=True)<br>    return<br><br>if __name__ == &#39;__main__&#39;:<br>  main()</pre><pre class="" style="margin-top:0px;padding:5px;border:0px;overflow:auto;width:auto;max-height:600px;word-wrap:normal"><span style="font-family:arial,sans-serif">I am running with the command:</span><br></pre><pre class="" style="margin-top:0px;padding:5px;border:0px;overflow:auto;width:auto;max-height:600px;word-wrap:normal">mpirun -np 4 ./run.py</pre><pre class="" style="margin-top:0px;padding:5px;border:0px;overflow:auto;width:auto;max-height:600px;word-wrap:normal"><span style="font-family:arial,sans-serif">This is the error message that I get:</span><br></pre><pre class="" style="margin-top:0px;padding:5px;border:0px;overflow:auto;width:auto;max-height:600px;word-wrap:normal">[localhost:51087] [[51455,0],0] ORTE_ERROR_LOG: Not found in file base/odls_base_default_fns.c at line 1762<br>[localhost:51087] [[51455,0],0] ORTE_ERROR_LOG: Not found in file orted/orted_comm.c at line 916<br>[localhost:51087] [[51455,0],0] ORTE_ERROR_LOG: Not found in file base/odls_base_default_fns.c at line 1762<br>[localhost:51087] [[51455,0],0] ORTE_ERROR_LOG: Not found in file orted/orted_comm.c at line 916<br>--------------------------------------------------------------------------<br>A system call failed during shared memory initialization that should<br>not have.  It is likely that your MPI job will now either abort or<br>experience performance degradation.<br><br>  Local host:  localhost<br>  System call: open(2) <br>  Error:       No such file or directory (errno 2)<br>--------------------------------------------------------------------------<br><br><br>I<span style="font-family:arial,sans-serif"> cannot understand where the error is happening. MontePython by itself should not use mpibecause it should be serial.</span><br></pre></div></div>

